<?xml version="1.0" encoding="utf-8"?>
<robot xmlns:xacro="http://www.ros.org/wiki/xacro" >

  <link name="base_link">
    <inertial>
      <origin
        xyz="-0.01422 -0.00104 0.1648"
        rpy="0 0 0" />
      <mass
        value="5" />
      <inertia
        ixx="0.0"
        ixy="-0.00000060186"
        ixz="-0.00371774"
        iyy="0.0"
        iyz="0.00092280"
        izz="0.05153320" />

    </inertial>
    <visual>
      <origin
        xyz="0 0 0"
        rpy="-1.5708 0 3.1415" />
      <geometry>
        <mesh
          filename="file://${repo_path}Robot/dev_ws/src/robot_description/meshes/base_link.STL" />
      </geometry>
      <material
        name="">
        <color
          rgba="1 1 1 1" />
      </material>
    </visual>
    <collision>
      <origin
        xyz="0 0 0"
        rpy="-1.5708 0 3.1415" />
      <geometry>
        <mesh
          filename="file://${repo_path}Robot/dev_ws/src/robot_description/meshes/base_link.STL" />
      </geometry>
    </collision>
  </link>
  <link name="left_wheel_link">
    <inertial>
      <origin
        xyz="0.0225 -4.8117E-16 0"
        rpy="0 0 0" />
      <mass
        value="0.2" />
      <inertia
        ixx="4.2948E-05"
        ixy="-6.9997E-22"
        ixz="2.4627E-21"
        iyy="3.147E-05"
        iyz="-2.647E-23"
        izz="3.147E-05" />
    </inertial>
    <visual>
      <origin
        xyz="-0.018 0 0"
        rpy="0 0 0" />
      <geometry>
        <mesh
          filename="file://${repo_path}Robot/dev_ws/src/robot_description/meshes/left_wheel_link.STL" />
      </geometry>
      <material
        name="">
        <color
          rgba="0.79216 0.81961 0.93333 1" />
      </material>
    </visual>
    <collision>
      <origin
      xyz="-0.018 0 0"
      rpy="0 0 0" />
      <geometry>
        <mesh
          filename="file://${repo_path}Robot/dev_ws/src/robot_description/meshes/left_wheel_link.STL" />
      </geometry>
    </collision>
  </link>
  <joint name="left_wheel_joint"
    type="continuous">
    <origin
      xyz="0.1175 0 0.02"
      rpy="1.564 0.0 3.1416" />
    <parent
      link="base_link" />
    <child
      link="left_wheel_link" />
    <axis
      xyz="1 0 0" />
    <limit
      lower="0"
      upper="0"
      effort="0"
      velocity="0" />
  </joint>
  <link name="right_wheel_link">
    <inertial>
      <origin
        xyz="0.0225 -4.1842E-16 3.4694E-18"
        rpy="0 0 0" />
      <mass
        value="0.2" />
      <inertia
        ixx="4.2948E-05"
        ixy="3.0585E-20"
        ixz="1.8206E-21"
        iyy="3.147E-05"
        iyz="1.6411E-21"
        izz="3.147E-05" />
    </inertial>
    <visual>
      <origin
        xyz="-0.018 0 0"
        rpy="0 0 0" />
      <geometry>
        <mesh
          filename="file://${repo_path}Robot/dev_ws/src/robot_description/meshes/right_wheel_link.STL" />
      </geometry>
      <material
        name="">
        <color
          rgba="0.79216 0.81961 0.93333 1" />
      </material>
    </visual>
    <collision>
      <origin
        xyz="0 0 0"
        rpy="0 0 0" />
      <geometry>
        <mesh
          filename="file://${repo_path}Robot/dev_ws/src/robot_description/meshes/right_wheel_link.STL" />
      </geometry>
    </collision>
  </link>
  <joint name="right_wheel_joint"
    type="continuous">
    <origin
      xyz="-0.1175 0 0.02"
      rpy="1.564 0.0 3.1416" />
    <parent
      link="base_link" />
    <child
      link="right_wheel_link" />
    <axis
      xyz="1 0 0" />
  </joint>
  <link name="gripper_left_link">
    <inertial>
      <origin
        xyz="0.0069271 -0.002 -0.0058473"
        rpy="0 0 0" />
      <mass
        value="0.034943" />
      <inertia
        ixx="2.1133E-05"
        ixy="-1.9167E-06"
        ixz="2.8841E-06"
        iyy="1.4367E-05"
        iyz="6.2513E-06"
        izz="1.2673E-05" />
    </inertial>
    <visual>
      <origin
        xyz="0 0 0"
        rpy="1.5708 3.1415 0" />
      <geometry>
        <mesh
          filename="file://${repo_path}Robot/dev_ws/src/robot_description/meshes/gripper_left_link.STL" />
      </geometry>
      <material
        name="">
        <color
          rgba="1 0 0 1" />
      </material>
    </visual>
    <collision>
      <origin
        xyz="0 0 0"
        rpy="0 0 0" />
      <geometry>
        <mesh
          filename="file://${repo_path}Robot/dev_ws/src/robot_description/meshes/gripper_left_link.STL" />
      </geometry>
    </collision>
  </link>
  <joint name="gripper_left_joint"
    type="prismatic">
    <origin
      xyz="0.085 0.105 0.0"
      rpy="-3.1416 0 0" />
    <parent
      link="base_link" />
    <child
      link="gripper_left_link" />
    <axis
      xyz="0 0 -1" />
    <limit
      lower="0.05"
      upper="0.25"
      effort="100"
      velocity="1" />
  </joint>
  <link name="gripper_right_link">
    <inertial>
      <origin
        xyz="0.0069271 0.0030988 0.00025266"
        rpy="0 0 0" />
      <mass
        value="0.034943" />
      <inertia
        ixx="2.1133E-05"
        ixy="-1.9167E-06"
        ixz="2.8841E-06"
        iyy="1.4367E-05"
        iyz="6.2513E-06"
        izz="1.2673E-05" />
    </inertial>
    <visual>
      <origin
        xyz="0 0 0"
        rpy="1.5708 3.1415 0" />
      <geometry>
        <mesh
          filename="file://${repo_path}Robot/dev_ws/src/robot_description/meshes/gripper_right_link.STL" />
      </geometry>
      <material
        name="">
        <color
          rgba="0.79216 0.81961 0.93333 1" />
      </material>
    </visual>
    <collision>
      <origin
        xyz="0 0 0"
        rpy="0 0 0" />
      <geometry>
        <mesh
          filename="file://${repo_path}Robot/dev_ws/src/robot_description/meshes/gripper_right_link.STL" />
      </geometry>
    </collision>
  </link>
  <joint name="gripper_right_joint"
    type="prismatic">
    <origin
      xyz="-0.085 0.105 0.0"
      rpy="-3.1416 0 0" />
    <parent
      link="base_link" />
    <child
      link="gripper_right_link" />
    <axis
      xyz="0 0 -1" />
    <limit
      lower="0.05"
      upper="0.25"
      effort="100"
      velocity="1" />
  </joint>
  <link name="lidar_link">
    <inertial>
      <origin
        xyz="9.9508E-08 4.832E-08 -0.015186"
        rpy="0 0 0" />
      <mass
        value="0.041055" />
      <inertia
        ixx="7.8469E-06"
        ixy="-1.4154E-11"
        ixz="3.1419E-12"
        iyy="7.8472E-06"
        iyz="9.3363E-12"
        izz="8.5515E-06" />
    </inertial>
    <visual>
      <origin
        xyz="0 0 0"
        rpy="3.1415 0 0" />
      <geometry>
        <mesh
          filename="file://${repo_path}Robot/dev_ws/src/robot_description/meshes/lidar_link.STL" />
      </geometry>
      <material
        name="">
        <color
          rgba="0.25098 0.25098 0.25098 1" />
      </material>
    </visual>
    <collision>
      <origin
        xyz="0 0 0"
        rpy="0 0 0" />
      <geometry>
        <mesh
          filename="file://${repo_path}Robot/dev_ws/src/robot_description/meshes/lidar_link.STL" />
      </geometry>
    </collision>
  </link>
  <joint name="lidar_joint"
    type="continuous">
    <origin
      xyz="0 0 0.383"
      rpy="0 0 -3.1416" />
    <parent
      link="base_link" />
    <child
      link="lidar_link" />
    <axis
      xyz="0 0 1" />
  </joint>
  <link name="imu_link">
    <inertial>
      <origin
        xyz="9.9747E-18 1.9429E-16 0.0025"
        rpy="0 0 0" />
      <mass
        value="0.00374" />
      <inertia
        ixx="1.5864E-07"
        ixy="1.1606E-24"
        ixz="-9.1005E-24"
        iyy="3.6808E-07"
        iyz="7.7908E-23"
        izz="5.1113E-07" />
    </inertial>
    <visual>
      <origin
        xyz="0 0 0"
        rpy="0 0 0" />
      <geometry>
        <mesh
          filename="file://${repo_path}Robot/dev_ws/src/robot_description/meshes/imu_link.STL" />
      </geometry>
      <material
        name="">
        <color
          rgba="0.79216 0.81961 0.93333 1" />
      </material>
    </visual>
    <collision>
      <origin
        xyz="0 0 0"
        rpy="0 0 0" />
      <geometry>
        <mesh
          filename="file://${repo_path}Robot/dev_ws/src/robot_description/meshes/imu_link.STL" />
      </geometry>
    </collision>
  </link>
<joint name="imu_joint"
    type="fixed">
    <origin
      xyz="-0.0032751 0.05685 0.029"
      rpy="0 0 0" />
    <parent
      link="base_link" />
    <child
      link="imu_link" />
    <axis
      xyz="0 0 0" />
  </joint>

</robot>
